Workbook

Sheet _src
U1: =MATCH('5. Tren Portofolio'!$C$9,$A$81:$A$104,0) -> 1
A2: scen | U2: =MATCH('5. Tren Portofolio'!$F$9,$A$81:$A$104,0) -> 24
A3: label | B3: lolos | C3: npl
A4: S0 Tanpa filter | B4: 1 | C4: 0.0341
A5: S1 Others (kini) | B5: 0.869 | C5: 0.0157
A6: S2 + Kol 12bln <= 2 | B6: 0.835 | C6: 0
A7: S3 + DPD 3bln = 0 | B7: 0.782 | C7: 0
A8: S4 + Kol 12bln = 1 | B8: 0.729 | C8: 0
A11: trend_npl
A12: month_label | B12: customer_npl_pct
B13: 0.0972
B14: 0.0944
A15: Jan-22 | B15: 0.0968
B16: 0.0932
B17: 0.0909
A18: Apr-22 | B18: 0.1014
B19: 0.1095
B20: 0.1042
A21: Jul-22 | B21: 0.1052
B22: 0.1059
B23: 0.0985
A24: Oct-22 | B24: 0.0956
B25: 0.0987
B26: 0.1017
A27: Jan-23 | B27: 0.1071
B28: 0.1121
B29: 0.1093
A30: Apr-23 | B30: 0.1172
B31: 0.1131
B32: 0.1162
A33: Jul-23 | B33: 0.1167
B34: 0.1152
B35: 0.1241
A36: Oct-23 | B36: 0.1165
A39: share_band
A40: flag | B40: 0. Lancar | C40: 1. Perhatian Khusus | D40: 2. NPL (Kol 3-5) | E40: 3. Tanpa Riwayat
A41: 1. Hapus buku | B41: 0 | C41: 0.0164 | D41: 0.9836 | E41: 0
A42: 2. Restrukturisasi | B42: 0.5625 | C42: 0.3125 | D42: 0.125 | E42: 0
A43: 3. Tanpa keduanya | B43: 0.8647 | C43: 0.0902 | D43: 0.0255 | E43: 0.0196
A46: segmen
...

Sheet 1. Ringkasan
B2: Kriteria whitelist masih meloloskan pemohon yang sudah macet
B3: 587 pemohon KTA · posisi aplikasi November 2023 · sumber: SLIK/iDeb (587 baris x 25 kolom)
B5: RINGKASAN EKSEKUTIF | SLIK AGGREGATED TABLE
B6: Tambahkan syarat Kol maksimal 2 selama 12 bulan: NPL yang lolos turun dari 13 pemohon menjadi 0, basis pemohon hanya menyusut 3,4 poin persen
B7: Flag whitelist sudah memisahkan risiko dengan baik, tetapi 13 dari 510 pemohon ber-flag "3.Customer Others" tercatat Kol 3-5 di 6 bulan terakhir (8 masih aktif macet). Menambahkan syarat "Kol maksimal 2 selama 12 bulan" menutup celah itu sepenuhnya.
B9: PEMOHON DIANALISIS | E9: LOLOS KRITERIA WHITELIST SEKARANG | H9: SUDAH MACET TAPI TETAP LOLOS | K9: NPL YANG TERHAPUS OLEH KRITERIA USULAN
B10: 587 | E10: 510 | H10: 13 | K10: 1
B11: 1 baris = 1 NIK · posisi November 2023 | E11: 86,9% dari basis · hanya flag "3.Customer Others" | H11: Kol 3-5 dalam 6 bulan terakhir · 8 masih macet aktif | K11: Basis pemohon tetap 83,5% (490 dari 587)
B13: Simulasi kriteria whitelist: mana yang paling seimbang? | I13: Kualitas portofolio 24 bulan sebelum aplikasi
B14: Batang = % pemohon yang lolos (semakin tinggi semakin longgar) · garis = % NPL aktif yang masih lolos (semakin rendah semakin aman) | I14: % pemohon dengan Kol 3-5 pada bulan laporan SLIK · garis putus-putus = tren
B28: Tiga hal yang perlu diputuskan tim risk
B29: 1 Tutup celah flag "Others" | F29: 2 Eksposur dan angsuran bukan pemeringkat risiko | J29: 3 Pemohon tanpa jejak pinjaman perlu jalur sendiri
B30: Flag Writeoff dan Restru sudah tajam: 60 dari 61 pemohon ber-flag Writeoff berada di Kol 5. Celahnya ada di flag "Others": 13 pemohon sudah Kol 3-5 dan 8 masih macet aktif. Flag saja tidak cukup — perlu syarat riwayat kolektibilitas. | F30: Gini slik_exposure 0,40 tetapi arahnya terbalik: makin besar eksposur makin kecil NPL — efek pemohon tanpa jejak, bukan sebab-akibat. slik_installment hanya Gini 0,22. Dua metrik ini tepat sebagai ukuran kapasitas dan afordabilitas, bukan cut-off risiko. Yang memisahkan risiko adalah kualitas pembayaran dan jumlah fasilitas (Gini 0,28). | J30: 107 pemohon (18%) punya slik_exposure Rp 0 — tidak ada kartu kredit maupun KTA aktif. Tingkat pernah-bermasalah mereka 28,0% versus 14,0% rata-rata. Data SLIK tipis bukan berarti bersih; butuh verifikasi pendapatan atau limit awal yang lebih kecil.
B34: Definisi: "NPL aktif" = kolektibilitas 3-5 pada fasilitas yang masih berjalan per November 2023 (outcome independen). "Pernah bermasalah 12 bln" = Kol 3-5 pada riwayat 12 bulan sebelum aplikasi. Semua istilah dijelaskan di tab "Kamus Metrik"; keterbatasan data di tab "Catatan & Asumsi".

Sheet 2. Matrix Report
B2: Flag whitelist bekerja, satu kantong risiko masih lolos
B3: Jumlah pemohon per kombinasi flag whitelist x kolektibilitas terburuk 6 bulan terakhir · total harus 587
B5: TOPIK 1 | MATRIX REPORT
B6: 60 dari 61 pemohon ber-flag hapus buku memang berada di Kol 5 — tetapi 13 pemohon "tanpa keduanya" juga sudah Kol 3-5
B7: Baca baris demi baris: konsentrasi risiko yang pekat (warna amber) idealnya hanya muncul di dua baris pertama. Kemunculannya di baris ketiga berarti kriteria whitelist saat ini belum melihat riwayat kolektibilitas.
B9: Sebaran 587 pemohon: flag whitelist x kolektibilitas terburuk 6 bulan terakhir
B10: Semakin pekat warna sel, semakin banyak pemohon di kombinasi tersebut · kolom kanan = porsi Kol 3-5 pada baris itu
B11: Flag whitelist (kode sesuai spesifikasi) | E11: Kol 1 Lancar | F11: Kol 2 Perhatian khusus | G11: Kol 3 Kurang lancar | H11: Kol 4 Diragukan | I11: Kol 5 Macet | J11: Tanpa riwayat 6 bulan | K11: Total pemohon | L11: Porsi Kol 3-5 (kualitas baris)
B12: 1. Pernah hapus buku ("Writeoff") | E12: 0 | F12: 1 | G12: 0 | H12: 0 | I12: 60 | J12: 0 | K12: 61 | L12: 0.98360656
B13: 2. Pernah restrukturisasi ("Restru") | E13: 9 | F13: 5 | G13: 0 | H13: 1 | I13: 1 | J13: 0 | K13: 16 | L13: 0.125
B14: 3. Tanpa keduanya ("Others") | E14: 441 | F14: 46 | G14: 1 | H14: 6 | I14: 6 | J14: 10 | K14: 510 | L14: 0.025490196
B15: Total | E15: 450 | F15: 52 | G15: 1 | H15: 7 | I15: 67 | J15: 10 | K15: 587 | L15: 0.12776831
B16: "Tanpa riwayat 6 bulan" = pemohon terdaftar di SLIK tetapi tidak ada satu pun bulan laporan pada Mei-Oktober 2023 (10 pemohon). Kolom ini sengaja ditampilkan, bukan dibuang, agar total tetap 587.
B18: Komposisi risiko tiap flag (dinormalkan 100%) | H18: Rincian celah: pemohon "tanpa keduanya" yang sudah Kol 3-5
B19: Membandingkan bentuk risiko tanpa terganggu perbedaan ukuran kelompok | H19: Kelompok inilah yang lolos kriteria whitelist saat ini
H20: 13 pemohon di baris ke-3 sudah tercatat Kol 3-5 dalam 6 bulan terakhir, 8 di antaranya masih macet pada fasilitas aktif per November 2023. Semua lolos kriteria whitelist yang berlaku sekarang.
H22: Kolektibilitas terburuk 6 bulan terakhir | J22: Pemohon | K22: Masih macet aktif | L22: Rata-rata eksposur SLIK
H23: Kol 3 - Kurang Lancar | J23: 1 | K23: 1 | L23: 16230256
H24: Kol 4 - Diragukan | J24: 6 | K24: 4 | L24: 59447216
H25: Kol 5 - Macet | J25: 6 | K25: 3 | L25: 31133582
H26: Total celah | J26: 13 | K26: 8 | L26: 43055004
H27: Cara menutupnya: syaratkan kolektibilitas maksimal 2 sepanjang 12 bulan terakhir (kolom collection_status_allcondition_last_12months_max). Simulasi di tab "7. Simulasi Kebijakan" menunjukkan seluruh NPL hilang dan basis pemohon tetap 83,5% (490 pemohon). Sebagai perbandingan, menambahkan syarat DPD 3 bulan = 0 tidak lagi menurunkan NPL tetapi memotong basis ke 78,2%.
B33: Sumber: view BigQuery vw_matrix_whitelist_x_kol6m, diekspor ke output/matrix_whitelist_x_kol6m.csv. Kolektibilitas mengikuti KODE REFERENSI OJK REF#21.

Sheet 3. Segmentasi
B2: Jumlah fasilitas kredit membedakan segmen paling tegas
B3: Lima segmen dibentuk berjenjang dari kondisi fasilitas dan riwayat kolektibilitas 12 bulan · setiap pemohon masuk tepat satu segmen
B5: TOPIK 2 | SEGMENTASI PERILAKU PEMOHON
B6: Segmen "Macet / NPL" memegang rata-rata 64 fasilitas kredit — 3,6 kali segmen bersih (18 fasilitas)
B7: 72,6% pemohon berada di segmen bersih dan lancar, sementara 14,1% sudah macet atau dihapusbukukan. Pola "credit shopping" (banyak fasilitas di banyak lembaga) adalah pembeda paling kuat dan bisa dipakai langsung sebagai aturan penyaring.
B9: Profil lima segmen perilaku SLIK
B10: Kolom "NPL aktif" memakai outcome independen (kolektibilitas fasilitas aktif per November 2023), bukan variabel yang membentuk segmen
B11: Segmen perilaku (kode sesuai kolom slik_behavior_segment) | E11: Pemohon | F11: % basis | G11: Rata-rata fasilitas | H11: Rata-rata eksposur SLIK | J11: Rata-rata angsuran SLIK / bulan | L11: NPL aktif | M11: Pernah telat 3 bulan
B12: A. Bersih & lancar (A. Clean & Current) | E12: 426 | F12: 0.726 | G12: 17.7 | H12: 1.3746699e+08 | J12: 7985900.9 | L12: 0 | M12: 0
B13: B. Pernah telat ringan (B. Past Due Ringan) | E13: 64 | F13: 0.109 | G13: 34.8 | H13: 1.7432653e+08 | J13: 20966298 | L13: 0 | M13: 0.484
B14: C. Pernah restrukturisasi (C. Restructured) | E14: 14 | F14: 0.024 | G14: 28.3 | H14: 2.0979743e+08 | J14: 63470614 | L14: 0 | M14: 0.357
B15: D. Macet / NPL (D. NPL / Delinquent) | E15: 22 | F15: 0.037 | G15: 64.2 | H15: 65364900 | J15: 16039193 | L15: 0.455 | M15: 0.636
B16: E. Sudah hapus buku (E. Writeoff) | E16: 61 | F16: 0.104 | G16: 50.4 | H16: 42485773 | J16: 5395106 | L16: 0.164 | M16: 1
B17: Urutan pembentukan segmen: E jika ada fasilitas hapus buku -> D jika Kol 3-5 dalam 12 bulan -> C jika ada restrukturisasi -> B jika pernah telat pada 3 bulan terakhir -> sisanya A. Karena berjenjang, satu pemohon tidak bisa terhitung dua kali.
B19: Rata-rata jumlah fasilitas kredit vs NPL aktif per segmen | I19: Ukuran tiap segmen
B20: Batang = rata-rata jumlah fasilitas (semua kondisi) · garis = % pemohon dengan NPL aktif | I20: Jumlah pemohon · segmen bermasalah disorot
B33: Catatan kejujuran analisis: segmen D dan E sebagian dibentuk dari riwayat kolektibilitas, sehingga tingkat NPL-nya tidak sepenuhnya independen. Yang independen dari definisi segmen adalah rata-rata jumlah fasilitas dan nilai eksposur — itulah sebabnya dua kolom tersebut yang dipakai sebagai temuan. Sumber: segment_summary.csv · view BigQuery: vw_segment_summary.

Sheet 4. Scorecard
B2: Eksposur dan angsuran SLIK bukan pemeringkat risiko
B3: Gini = kemampuan memisahkan pemohon baik dan buruk (0 = tidak bisa memisahkan, 1 = sempurna) · target: NPL aktif per November 2023
B5: TOPIK 3 | UJI KELAYAKAN VARIABEL SCORECARD
B6: Desil eksposur terkecil punya tingkat pernah-bermasalah 27,1% dan desil terbesar 3,4% — arahnya terbalik, tetapi tangganya tidak rapi
B7: Pola ini konsisten dengan praktik pasar: pemohon dengan eksposur besar adalah mereka yang sudah lolos seleksi lembaga lain, sedangkan eksposur nol berarti belum ada jejak. Penurunannya tidak monoton dan pada target NPL aktif nyaris hilang, jadi kedua metrik SLIK sebaiknya dipakai untuk menghitung kapasitas dan afordabilitas, sementara pemeringkatan risiko diserahkan pada variabel perilaku.
B9: Rank ordering: tingkat bermasalah per desil eksposur | H9: Daya pisah tiap kandidat variabel
B10: Idealnya garis turun rapi dari kiri ke kanan (atau naik) — di sini justru mendatar/terbalik | H10: Diurutkan dari Gini tertinggi · arah menunjukkan tanda hubungan
H11: Kandidat variabel | K11: Gini | L11: IV | M11: Arah
H12: Fasilitas aktif pernah telat >10 hr | K12: 0.906 | L12: 2.671 | M12: Searah
H13: Eksposur SLIK | K13: 0.395 | L13: 0.635 | M13: Terbalik
H14: Jumlah fasilitas kredit | K14: 0.278 | L14: 0.733 | M14: Searah
H15: Angsuran SLIK per bulan | K15: 0.223 | L15: 0.529 | M15: Searah
H16: Restrukturisasi tanpa agunan | K16: 0.121 | L16: 0.6 | M16: Searah
H17: Outstanding tanpa agunan | K17: 0.079 | L17: 0.384 | M17: Searah
H18: Umur kredit terlama (bulan) | K18: 0.042 | L18: 0.549 | M18: Terbalik
H19: Variabel teratas (fasilitas aktif yang pernah telat >10 hari) memang punya Gini 0,91, tetapi hampir satu definisi dengan target sehingga tidak layak dipakai sebagai prediktor. Kandidat yang benar-benar berguna dan tersedia saat aplikasi adalah jumlah fasilitas kredit (Gini 0,28 · IV 0,73). Arah "terbalik" berarti nilai makin besar justru makin sedikit NPL — tanda variabel kapasitas, bukan variabel risiko.
B24: Sebaran eksposur SLIK antar pemohon | H24: Sebaran angsuran SLIK per bulan
B25: Batang amber = pemohon tanpa eksposur sama sekali (107 pemohon, 18% basis) | H25: Batang amber = pemohon tanpa angsuran berjalan (60 pemohon)
B34: Penyebab utama nilai Rp 0: 107 pemohon (18% basis) tidak punya kartu kredit maupun KTA berstatus aktif, sehingga kedua komponen slik_exposure nol sekaligus. Kelompok inilah yang menempati desil terbawah dan membuat arah hubungan eksposur-NPL terlihat terbalik. Sumber: scorecard_deciles.csv, scorecard_power.csv.

Sheet 5. Tren Portofolio
B2: Kualitas kredit memburuk selama 24 bulan sebelum aplikasi
B3: Agregasi bulanan riwayat SLIK Nov-21 - Oct-23 · bulan aplikasi (November 2023) sengaja tidak diikutkan agar tidak bocor ke masa depan
B5: TOPIK 4 | TREN KUALITAS PORTOFOLIO SLIK
B6: Rata-rata hari keterlambatan naik dari 27 hari menjadi 52 hari, dan porsi pemohon Kol 3-5 naik 1,9 poin persen
B7: Artinya keputusan kredit tidak bisa hanya melihat posisi terakhir: tren 24 bulan menunjukkan tekanan yang menumpuk. Gunakan kontrol rentang bulan di bawah untuk memeriksa periode tertentu.
B9: Dari bulan | C9: Nov-21 | E9: sampai | F9: Oct-23 | H9: Klik sel amber untuk memilih rentang — grafik dan ringkasan ikut menyesuaikan (tetap berfungsi di Google Sheets).
B11: Rata-rata hari telat dan porsi pemohon Kol 3-5 per bulan laporan | I11: Ringkasan rentang yang dipilih
B12: Batang = rata-rata hari keterlambatan (skala kiri) · garis = % pemohon Kol 3-5 (skala kanan) | I12: Semua angka dihitung ulang otomatis mengikuti kontrol di atas
I13: Indikator | L13: Nilai
I14: Bulan ditampilkan | L14: =(_src!$U$2-_src!$U$1)+1 -> 24
I16: % pemohon Kol 3-5 di bulan awal | L16: =INDEX(_src!$C$81:$C$104,_src!$U$1) -> 0.0972
I18: % pemohon Kol 3-5 di bulan akhir | L18: =INDEX(_src!$C$81:$C$104,_src!$U$2) -> 0.1165
I20: Perubahan (poin persen) | L20: =(INDEX(_src!$C$81:$C$104,_src!$U$2)-INDEX(_src!$C$81:$C$104,_src!$U$1))*100 -> 1.93
I22: Rata-rata hari telat pada rentang | L22: =AVERAGEIFS(_src!$D$81:$D$104,_src!$B$81:$B$104,">="&_src!$U$1,_src!$B$81:$B$104,"<="&_src!$U$2) -> 31.2
I24: Bulan terburuk pada rentang | L24: =INDEX(_src!$A$81:$A$104,MATCH(MAX(INDEX(_src!$C$81:$C$104,_src!$U$1):INDEX(_src!$C$81:$C$104,_src!$U$2)),INDEX(_src!$C$81:$C$104,_src!$U$1):INDEX(_src!$C$81:$C$104,_src!$U$2),0)+_src!$U$1-1) -> Sep-23
B28: Mengapa tren ini penting untuk keputusan hari ini: pemohon yang hari ini berstatus Kol 1 bisa saja baru pulih dari keterlambatan beberapa bulan lalu. Kolom collection_status_allcondition_last_12months_max menangkap hal itu, dan itulah variabel yang dipakai pada kriteria whitelist usulan. | H28: Cakupan data: setiap bulan hanya memuat pemohon yang benar-benar dilaporkan lembaga keuangan pada bulan tersebut (rata-rata 515 dari 587 pemohon), sehingga angka persentase sudah dinormalkan terhadap jumlah pelapor bulan itu — bukan terhadap 587.
B32: Sumber: slik_monthly_trend.csv (tab data_tren) · dibentuk dari 24 pasang kolom riwayat tahunBulanXX / kolektibilitasXX / hariTelatXX pada tabel SLIK mentah.

Sheet 6. Demografi
B2: Demografi memberi sinyal lemah, kecuali kelompok usia 50-54
B3: Tingkat "pernah bermasalah 12 bulan" per kelompok demografi, disertai jumlah sampel dan selang kepercayaan 95% agar kelompok kecil tidak dibaca berlebihan
B5: TOPIK 5 | PROFIL DEMOGRAFI VS RISIKO
B6: Usia 50-54 mencatat 30,8% pernah bermasalah versus 10,3% pada usia 25-29 — satu-satunya selisih yang tidak beririsan dengan selang kepercayaan kelompok lain
B7: Perbedaan gender dan status pernikahan masih di dalam rentang ketidakpastian pada ukuran sampel 587; pada pendidikan hanya "Tanpa Gelar" yang selangnya seluruhnya di atas rata-rata basis, dan batas bawahnya pun hanya menyerempet. Demografi karena itu dipakai untuk memantau komposisi, bukan menolak.
B9: Tingkat pernah bermasalah per kelompok usia | H9: Per tingkat pendidikan (hanya kelompok dengan sampel >= 15)
B10: Jumlah sampel ditulis di label agar kelompok kecil terlihat jelas | H10: Diploma 1 (n=5) dan Diploma 2 (n=1) dikeluarkan karena terlalu kecil untuk disimpulkan
B25: Gender dan status pernikahan: apakah selisihnya nyata?
B26: Selang kepercayaan 95% (metode Wilson) · jika dua selang saling beririsan, selisihnya belum dapat disimpulkan pada ukuran sampel ini
B27: Kelompok | E27: Jumlah pemohon | F27: Pernah bermasalah | G27: Tingkat | H27: Batas bawah 95% | I27: Batas atas 95% | J27: Cara membacanya
B28: Gender: perempuan | E28: 196 | F28: 30 | G28: 0.1531 | H28: 0.1094 | I28: 0.2101 | J28: Beririsan lebar dengan laki-laki: selisih 2,0 poin persen belum dapat disimpulkan.
B29: Gender: laki-laki | E29: 391 | F29: 52 | G29: 0.133 | H29: 0.1029 | I29: 0.1702 | J29: Kelompok mayoritas (67% basis) — menjadi acuan pembanding.
B30: Status: menikah | E30: 259 | F30: 44 | G30: 0.1699 | H30: 0.1291 | I30: 0.2204 | J30: Selisih 5,3 poin di atas "belum menikah", tetapi selang masih beririsan tipis: arah konsisten, belum konklusif.
B31: Status: belum menikah | E31: 317 | F31: 37 | G31: 0.1167 | H31: 0.0859 | I31: 0.1567 | J31: Kelompok terbesar dan paling rendah risikonya di antara status pernikahan.
B32: Status: lainnya (cerai/janda/lain) | E32: 11 | F32: 1 | G32: 0.0909 | H32: 0.0162 | I32: 0.3774 | J32: Hanya 11 pemohon — selang sangat lebar, tidak layak dipakai untuk keputusan.
B34: Keterbatasan: dataset demografi tidak memuat penghasilan, sehingga Debt Burden Ratio (angsuran SLIK / penghasilan) tidak dapat dihitung. Selain itu 14 dari 587 pemohon tidak punya baris di tabel demografi kedua, sehingga kolom pendidikan/pekerjaan untuk mereka kosong dan tidak ikut dihitung.

Sheet 7. Simulasi Kebijakan
B2: Atur kriteria dan lihat dampaknya ke basis pemohon dan NPL
B3: Empat kontrol di bawah menghitung ulang seluruh KPI dan grafik dari 587 baris data pemohon · nilai awal = kriteria yang direkomendasikan
B5: REKOMENDASI | SIMULASI KRITERIA WHITELIST
B6: Kriteria usulan: flag "3.Customer Others" DAN kolektibilitas maksimal 2 sepanjang 12 bulan terakhir — 490 pemohon lolos (83,5% basis) dengan nol NPL aktif
B7: Menambahkan syarat DPD 3 bulan = 0 tidak lagi menurunkan NPL tetapi memotong basis pemohon 5,3 poin persen — jadi syarat itu tidak perlu. Ubah kontrol di bawah untuk menguji kombinasi lain.
B9: FLAG WHITELIST | E9: MAKS. KOLEKTIBILITAS 12 BULAN | H9: MAKS. HARI TELAT 3 BULAN | K9: SEGMEN PERILAKU
B10: 3.Customer Others | E10: 2 | H10: 9999 | K10: Semua
B12: Hasil simulasi untuk kriteria yang dipilih
B13: Dihitung dengan SUMPRODUCT langsung dari tab data_customer — tetap hidup setelah diimpor ke Google Sheets
B14: PEMOHON LOLOS | E14: % BASIS PEMOHON YANG DIPERTAHANKAN | H14: NPL AKTIF YANG MASIH LOLOS | K14: PERNAH BERMASALAH 12 BULAN YANG LOLOS
B15: =SUMPRODUCT((('data_customer'!$B$2:$B$588=$B$10)+($B$10="Semua")>0)*('data_customer'!$H$2:$H$588<=$E$10)*('data_customer'!$I$2:$I$588<=$H$10)*(('data_customer'!$C$2:$C$588=$K$10)+($K$10="Semua")>0)) -> 490 | E15: =SUMPRODUCT((('data_customer'!$B$2:$B$588=$B$10)+($B$10="Semua")>0)*('data_customer'!$H$2:$H$588<=$E$10)*('data_customer'!$I$2:$I$588<=$H$10)*(('data_customer'!$C$2:$C$588=$K$10)+($K$10="Semua")>0))/587 -> 0.8348 | H15: =SUMPRODUCT((('data_customer'!$B$2:$B$588=$B$10)+($B$10="Semua")>0)*('data_customer'!$H$2:$H$588<=$E$10)*('data_customer'!$I$2:$I$588<=$H$10)*(('data_customer'!$C$2:$C$588=$K$10)+($K$10="Semua")>0)*'data_customer'!$Q$2:$Q$588) -> 0 | K15: =IF(SUMPRODUCT((('data_customer'!$B$2:$B$588=$B$10)+($B$10="Semua")>0)*('data_customer'!$H$2:$H$588<=$E$10)*('data_customer'!$I$2:$I$588<=$H$10)*(('data_customer'!$C$2:$C$588=$K$10)+($K$10="Semua")>0))=0,0,SUMPRODUCT((('data_customer'!$B$2:$B$588=$B$10)+($B$10="Semua")>0)*('data_customer'!$H$2:$H$588<=$E$10)*('data_customer'!$I$2:$I$588<=$H$10)*(('data_customer'!$C$2:$C$588=$K$10)+($K$10="Semua")>0)*'data_customer'!$R$2:$R$588)/SUMPRODUCT((('data_customer'!$B$2:$B$588=$B$10)+($B$10="Semua")>0)*('data_customer'!$H$2:$H$588<=$E$10)*('data_customer'!$I$2:$I$588<=$H$10)*(('data_customer'!$C$2:$C$588=$K$10)+($K$10="Semua")>0))) -> 0
B16: dari 587 pemohon dalam basis | E16: semakin tinggi semakin longgar kriteria | H16: target: 0 pemohon | K16: kontrol historis, bukan target utama
B18: Lima skenario baku sebagai pembanding | H18: Sebaran segmen pemohon yang lolos kriteria terpilih
B19: Baris amber = kriteria yang direkomendasikan (titik henti terbaik) | H19: Ikut berubah saat kontrol di atas diubah
B20: Skenario kriteria | E20: Pemohon lolos | F20: % basis | G20: NPL aktif yang lolos
B21: S0 Tanpa filter apa pun | E21: 587 | F21: 1 | G21: 0.0341
B22: S1 Flag Others saja (berlaku kini) | E22: 510 | F22: 0.869 | G22: 0.0157
B23: S2 Others + Kol 12 bln <= 2 | E23: 490 | F23: 0.835 | G23: 0
B24: S3 S2 + DPD 3 bln = 0 | E24: 459 | F24: 0.782 | G24: 0
B25: S4 Others + Kol 12 bln = 1 + DPD 0 | E25: 428 | F25: 0.729 | G25: 0
B26: Cara membaca: dari S1 ke S2, NPL aktif yang lolos turun dari 1,57% menjadi 0% dengan biaya 3,4 poin persen basis pemohon. Dari S2 ke S3 dan S4, NPL sudah nol sehingga tambahan syarat hanya memotong basis (masing-masing -5,3 dan -10,6 poin) tanpa manfaat risiko. Karena itu S2 adalah titik henti yang paling efisien.
B32: Rekomendasi akhir: pertahankan flag whitelist yang ada, tambahkan satu syarat "collection_status_allcondition_last_12months_max <= 2". Dampaknya: basis pemohon 86,9% menjadi 83,5%, NPL aktif yang lolos 1,57% menjadi 0%. Untuk 107 pemohon tanpa jejak SLIK, terapkan jalur verifikasi terpisah karena tingkat bermasalah mereka 28,0% di atas rata-rata basis 14,0%.
B34: Sumber: whitelist_scenarios.csv untuk lima skenario baku · KPI dan grafik kanan dihitung langsung dari tab data_customer dengan SUMPRODUCT.

Sheet Kamus Metrik
B2: Kamus metrik: dari nama kolom teknis ke bahasa sehari-hari
B3: 25 kolom wajib sesuai spesifikasi (nomor 1-25) ditambah kolom turunan yang dipakai untuk analisis · semua definisi mengikuti KODE REFERENSI OJK
B5: REFERENSI
B7: Nama kolom (teknis) | D7: Sebutan untuk orang awam | G7: Definisi dan cara hitung | L7: Dipakai di tab
B8: 25 KOLOM WAJIB SESUAI SPESIFIKASI
B9: 1. NIK | D9: Nomor identitas pemohon | G9: Kolom ktp pada tabel SLIK. Menjadi kunci utama tabel: satu baris = satu pemohon. | L9: Semua
B10: 2. flags_allcondition_count | D10: Jumlah fasilitas kredit | G10: Banyaknya fasilitas kredit pemohon di seluruh lembaga keuangan, tanpa memandang status aktif, lunas, atau hapus buku. | L10: 3, 4
B11: 3. flags_restructured_active_count | D11: Fasilitas aktif yang direstrukturisasi | G11: Fasilitas berstatus aktif (kondisi 0) yang pernah direstrukturisasi: sifatKredit = 1, atau frekuensiRestrukturisasi > 0, atau ada tanggal restrukturisasi terakhir. | L11: 3
B12: 4. flags_chargewriteoff_count | D12: Fasilitas yang dihapusbukukan | G12: Fasilitas dengan kondisi 3 (dihapusbukukan) atau 4 (hapus tagih). Menjadi dasar flag whitelist prioritas pertama. | L12: 1, 2
B13: 5. plafond_credit_card_active_max | D13: Limit kartu kredit aktif tertinggi | G13: Plafon terbesar di antara kartu kredit aktif. REF#15 memakai dua skema sandi sekaligus: sandi lama 30 (tersimpan sebagai X-30) dan Sandi Referensi P05. Seluruh kartu kredit aktif di dataset ini memakai P05, sehingga keduanya harus dibaca bersama. | L13: 4, Catatan
B14: 6. installment_active_max | D14: Angsuran bulanan terbesar | G14: Nilai angsuran terbesar di antara seluruh fasilitas aktif pemohon. | L14: data
B15: 7. balance_personal_loan_active_sum | D15: Total outstanding KTA aktif | G15: Jumlah baki debet fasilitas KTA aktif, yaitu penggunaan konsumsi, tanpa agunan, dan bukan kartu kredit. | L15: 4
B16: 8. plafond_credit_card_active_sum | D16: Total limit kartu kredit aktif | G16: Jumlah plafon seluruh kartu kredit aktif. Komponen pertama slik_exposure. | L16: 4
B17: 9. installment_personal_loan_active_sum | D17: Total angsuran pinjaman aktif | G17: Jumlah angsuran bulanan fasilitas pinjaman aktif non-kartu-kredit. Komponen kedua slik_installment. | L17: 4
B18: 10. balance_credit_card_active_sum | D18: Total outstanding kartu kredit aktif | G18: Jumlah baki debet kartu kredit aktif. Menjadi dasar perhitungan 5% pada slik_installment. | L18: 4
B19: 11. mob_active_avg | D19: Rata-rata umur fasilitas aktif (bulan) | G19: Rata-rata selisih bulan antara tanggal awal kredit dan bulan aplikasi (November 2023) untuk fasilitas aktif. | L19: data
B20: 12. dpd_nonbank_allcondition_last_12months_max | D20: Telat terlama di lembaga non-bank (12 bln) | G20: Hari keterlambatan tertinggi pada fasilitas dari perusahaan pembiayaan atau lembaga non-bank lain selama 12 bulan sebelum aplikasi. | L20: data
... B33: 25. whitelist_flag | D33: Kelompok whitelist | G33: Berurutan: "1.Customer has Writeoff" bila ada fasilitas hapus buku; bila tidak, "2.Customer has Restru" bila ada restrukturisasi; sisanya "3.Customer Others". | L33: 1, 2, 7
B35: KOLOM & ISTILAH TURUNAN (dibuat untuk keperluan analisis, di luar 25 kolom wajib)
B36: npl_now_active | D36: Gagal bayar aktif per Nov-2023 | G36: 1 bila pemohon punya minimal satu fasilitas yang masih aktif dengan Kol 3-5 pada bulan aplikasi. Inilah outcome yang dipakai menilai daya pisah metrik karena tidak dipakai membentuk segmen (independen). | L36: 1, 3, 4, 7
B37: ever_npl_12m | D37: Pernah gagal bayar dalam 12 bulan | G37: 1 bila Kol terburuk 12 bulan >= 3. Dipakai sebagai pembanding historis saja: kolom ini ikut membentuk segmen sehingga tidak layak menjadi target penilaian. | L37: 3, 4, 6
B38: ever_dpd_3m | D38: Pernah telat 3 bulan terakhir | G38: 1 bila telat terlama 3 bulan terakhir lebih dari 0 hari. | L38: 3
B39: slik_behavior_segment | D39: Segmen perilaku SLIK (A-E) | G39: Pengelompokan berjenjang: E Writeoff bila ada hapus buku, D NPL bila Kol 12 bulan >= 3, C Restructured bila ada restrukturisasi, B Past Due Ringan bila pernah telat, sisanya A Clean & Current. | L39: 3, 7
B40: risk_band_6m | D40: Band risiko 6 bulan | G40: Ringkasan Kol 6 bulan menjadi 4 kelompok: Lancar (Kol 1), Perhatian Khusus (Kol 2), Bermasalah/NPL (Kol 3-5), dan Tanpa Riwayat 6 Bulan. | L40: 2
B41: Gini | D41: Daya pisah metrik | G41: |2 x AUC - 1|. Nilai 0 berarti metrik tidak bisa memisahkan pemohon baik dan buruk, 1 berarti sempurna. Di bawah 0,10 dianggap belum dapat dipakai untuk scorecard. | L41: 4
B42: IV | D42: Kekuatan informasi | G42: Information Value: seberapa berbeda sebaran pemohon baik dan buruk antar-kelompok. Harus dibaca bersama Gini karena IV bisa tinggi walau hubungannya tidak searah. | L42: 4
B43: Kol 1-5 | D43: Kolektibilitas | G43: 1 Lancar, 2 Dalam Perhatian Khusus, 3 Kurang Lancar, 4 Diragukan, 5 Macet. Kol 3-5 disebut NPL (gagal bayar). | L43: Semua
B44: MOB | D44: Months on book (umur kredit) | G44: Umur fasilitas dalam bulan, dihitung dari tanggal awal kredit sampai bulan aplikasi. | L44: 3, 4
B45: Desil | D45: Kelompok sepersepuluh | G45: 587 pemohon diurutkan berdasarkan satu metrik lalu dibagi 10 kelompok berisi ~59 orang. Metrik yang baik akan menunjukkan gagal bayar naik konsisten dari desil 1 ke 10. | L45: 4
B47: Semua nilai uang dalam Rupiah. Posisi data = November 2023 (bulan pengajuan pinjaman). Sumber: tabel iDeb SLIK (grasp, facility, collectibility, demographic1, demographic2).

Sheet Catatan & Asumsi
B2: Kualitas data, asumsi, dan batasan analisis
B3: Semua angka pada dashboard ini dihitung dengan definisi di bawah · setiap temuan data disertai cara penanganannya agar hasil dapat direproduksi
B5: REFERENSI
B7: A. TEMUAN KUALITAS DATA DAN CARA PENANGANANNYA
B8: Topik | D8: Temuan pada data mentah | H8: Penanganan pada kueri / analisis
B9: Duplikat fasilitas | D9: 14.660 baris fasilitas, tetapi hanya 14.633 kreditId unik: 27 fasilitas muncul lebih dari satu kali (sebagian dengan tanggalUpdate rusak). | H9: Dedup dengan ROW_NUMBER per kreditId: diambil snapshot paling baru (tanggalUpdate terbesar), bila seri diambil baki debet terbesar agar eksposur tidak dianggap lebih kecil dari kenyataan.
B10: Tanggal rusak | D10: 3.483 sel tanggal berisi teks “#VALUE!”: tanggalKondisi 2.044, tanggalAkadAwal 1.128, tanggalUpdate 292, tanggalJatuhTempo 19. Menyentuh 2.612 baris dan 568 pemohon. | H10: Dibaca dengan SAFE.PARSE_DATE sehingga nilai rusak menjadi kosong, bukan menggagalkan kueri. Penting: tanggalAwalKredit bersih 100%, jadi perhitungan umur kredit (MOB) tidak terpengaruh.
B11: Dua skema sandi jenis kredit | D11: REF#15 memuat dua skema sekaligus: sandi lama (30 = Kartu Kredit, tersimpan sebagai X-30) dan Sandi Referensi baru (P05 = Kartu Kredit/Kartu Pembiayaan Syariah). Kedua skema muncul berdampingan di kolom jenisKredit. | H11: Seluruh 511 fasilitas X-30 sudah non-aktif, sementara 860 kartu kredit aktif memakai P05. Membaca sandi lama saja akan membuat ketiga kolom kartu kredit nol untuk seluruh 587 pemohon dan memindahkan Rp 73,0 miliar limit kartu kredit ke kolom KTA. Definisi yang dipakai di sini membaca X-30 dan P05 bersama-sama.
B12: Pemetaan lembaga | D12: Tabel ljk mapping berisi 2.701 baris untuk 2.264 kode: satu kode bisa punya beberapa nama (contoh kode 11 = Bank Danamon konvensional dan unit syariahnya). | H12: Nama lembaga di-dedup satu per kode hanya untuk keperluan label. Klasifikasi bank vs non-bank memakai pola kode (pembiayaan prefix 25 = non-bank; BPR 60, BPRS 62 dan bank umum = bank), bukan nama.
B13: Demografi tidak lengkap | D13: demographic2 hanya memuat 573 dari 587 pemohon, sehingga 14 pemohon tidak punya data pendidikan, pekerjaan, dan kota. | H13: Analisis demografi memakai basis yang tersedia dan jumlah pemohon per potongan ditulis apa adanya (n=573 untuk pendidikan). Tidak ada imputasi agar tidak menciptakan pola palsu.
B14: Tidak ada data penghasilan | D14: Dataset tidak memuat penghasilan atau pendapatan pemohon. | H14: Debt Burden Ratio / DSR tidak dapat dihitung. Beban cicilan hanya dilaporkan dalam nilai absolut (slik_installment). Bila penghasilan tersedia, rasio ini yang paling layak diuji lebih dulu.
B15: Riwayat terbatas | D15: Riwayat kolektibilitas dan tunggakan bulanan tersedia maksimal sampai Oktober 2023. | H15: Jendela 3, 6, 12, dan 24 bulan dihitung ke belakang dari Oktober 2023; bulan aplikasi (November 2023) tidak diikutkan agar tidak memakai informasi yang belum ada saat keputusan kredit dibuat.
B17: B. ASUMSI DEFINISI (dasar: KODE REFERENSI OJK + profil data)
B18: Istilah | D18: Definisi yang dipakai | H18: Alasan / dasar
B19: Posisi data | D19: November 2023 = bulan pengajuan pinjaman. | H19: Diminta eksplisit oleh spesifikasi: tabel harus menggambarkan kondisi pemohon pada posisi pengajuan.
B20: Fasilitas aktif | D20: kondisi = 0. | H20: REF#24: sandi 00 = Fasilitas Aktif.
B21: Hapus buku | D21: kondisi 3 (dihapusbukukan) atau 4 (hapus tagih). | H21: REF#24. Hapus buku tidak dihitung sebagai lunas karena kewajiban pemohon belum selesai.
B22: Sudah ditutup | D22: kondisi 1, 2, 5, 6, 7, 8, 9, 11, 12. | H22: Kelompok sandi yang berarti debitur sudah tidak memiliki kewajiban (lunas, dibatalkan, dialihkan).
B23: Restrukturisasi | D23: sifatKredit = 1, atau frekuensiRestrukturisasi > 0, atau tanggalRestrukturisasiAkhir terisi. | H23: REF#14. Tiga penanda dipakai sekaligus karena pelaporan antarlembaga tidak seragam; memakai satu penanda saja akan melewatkan sebagian kasus.
B24: Kartu kredit | D24: jenisKredit = X-30 atau P05. | H24: REF#15 memuat dua skema sandi yang dipakai berdampingan: sandi lama 30 = Kartu Kredit (tersimpan sebagai X-30) dan Sandi Referensi P05 = Kartu Kredit/Kartu Pembiayaan Syariah. Di dataset ini seluruh X-30 sudah non-aktif dan 860 kartu kredit aktif memakai P05, jadi membaca X-30 saja akan menihilkan seluruh kolom kartu kredit.
B25: Tanpa agunan | D25: jenisAgunan kosong. | H25: Tidak ada agunan yang dilaporkan pada fasilitas tersebut.
B26: KTA / personal loan | D26: Penggunaan konsumsi (jenisPenggunaan = 3), tanpa agunan, dan bukan kartu kredit. | H26: Kombinasi ini adalah definisi lazim KTA/cash loan, yaitu produk yang paling sebanding dengan pinjaman yang sedang diajukan.
B27: Lembaga non-bank | D27: Perusahaan pembiayaan (kode 6 digit berawalan 25), atau nama lembaga tanpa kata BANK / BPR / BPD dan kodenya tidak berawalan 60 / 62. | H27: Menangkap multifinance, modal ventura, dan lembaga keuangan lain. Bank umum, BPR (prefix 60), dan BPRS (prefix 62) dikelompokkan sebagai bank — pengecualian prefix diperlukan karena ada BPRS yang namanya tidak memuat kata BPR.
B28: Prioritas whitelist | D28: Berurutan: hapus buku -> "1.Customer has Writeoff"; jika tidak, restrukturisasi -> "2.Customer has Restru"; sisanya "3.Customer Others". | H28: Satu pemohon hanya boleh masuk satu kelompok. Urutan dipilih dari risiko terberat ke teringan sesuai contoh nilai pada spesifikasi.
B29: Kolom kosong vs nol | D29: Kolom hitung (count/sum) diisi 0; kolom nilai tertinggi/rata-rata dibiarkan kosong bila tidak ada fasilitas yang memenuhi kriteria. | H29: Kosong berarti “tidak ada data” dan 0 berarti “ada data, nilainya nol”. Membedakan keduanya mencegah rata-rata menjadi bias ke bawah.
B30: Penulisan angka | D30: Format Indonesia: titik sebagai pemisah ribuan, koma sebagai pemisah desimal. | H30: Menyesuaikan pembaca laporan di Indonesia.
B32: C. CATATAN ATAS SPESIFIKASI DAN BATASAN ANALISIS
B33: Topik | D33: Isi catatan | H33: Keputusan yang diambil
B34: Ketidakcocokan pada spesifikasi nomor 9 | D34: Nama kolom ditulis Installment_personal_loan_active_sum dengan huruf I kapital, sementara 24 nama kolom lainnya seluruhnya huruf kecil. | H34: Kolom dibuat installment_personal_loan_active_sum agar penamaan 25 kolom seragam. Nama kolom di BigQuery case-insensitive saat dirujuk, jadi SELECT dengan ejaan spesifikasi tetap berhasil pada tabel yang diserahkan.
B35: Ketidakcocokan pada spesifikasi nomor 16 | D35: Nama kolom yang diminta adalah collection_status_allcondition_last_12months_max, tetapi keterangannya berbunyi “maximum collection status ... last 6 months”, sama dengan keterangan nomor 15. | H35: Diikuti nama kolomnya, yaitu jendela 12 bulan, sehingga nomor 15 dan 16 memberi informasi berbeda (6 bulan dan 12 bulan). Bila yang dimaksud memang 6 bulan, cukup mengubah satu angka pada kueri.
B36: Dua kolom pada tab data_customer diisi nilai default | D36: Pada tab data_customer, kolektibilitas maks 12 bulan yang kosong diisi 1 (Lancar) dan hari telat maks 3 bulan yang kosong diisi 0 hari — 9 dan 12 sel, dari 587 baris. | H36: Hanya di tab itu, supaya filter SUMPRODUCT pada tab 7 memperlakukan pemohon tanpa riwayat sebagai tanpa catatan buruk, sama seperti perhitungan skenario di SQL dan Python. Tab data_agregat tetap memuat nilai asli tabel BigQuery (kosong = tidak ada riwayat).
B37: Kolom yang hampir seragam | D37: Dua kolom restrukturisasi hampir tidak bervariasi: flags_restructured_active_count nol pada 574 dari 587 pemohon dan flags_restructured_allcondition_unsecured_count nol pada 566 pemohon. | H37: Kolom tetap dibuat sesuai spesifikasi, tetapi tidak dipakai sebagai pembeda risiko karena kejadiannya terlalu jarang — dan hal ini dinyatakan terbuka, bukan disembunyikan.
B38: Target penilaian metrik | D38: Segmen perilaku dibentuk dari riwayat kolektibilitas 12 bulan, sehingga menilai metrik memakai ever_npl_12m akan memutar logika (target ikut membentuk prediktornya). | H38: Daya pisah metrik dinilai memakai npl_now_active, yaitu gagal bayar pada fasilitas yang masih aktif per November 2023. ever_npl_12m tetap ditampilkan hanya sebagai pembanding historis dan diberi label jelas.
B39: Ukuran sampel | D39: 587 pemohon dengan 20 kasus gagal bayar aktif. Untuk potongan demografi, jumlah kasus per kelompok tinggal satuan. | H39: Selang kepercayaan 95% (metode Wilson) ditampilkan pada analisis demografi, dan kelompok kecil tidak dijadikan dasar rekomendasi kebijakan.
B40: Sifat rekomendasi | D40: Dampak kriteria baru dihitung dari data historis 587 pemohon ini, bukan dari uji coba berjalan. | H40: Rekomendasi diposisikan sebagai usulan untuk diuji lewat champion-challenger sebelum diberlakukan penuh.
B42: Reproduksi: sql/01_load_tables.sql -> sql/02_slik_aggregated_table.sql -> sql/03_analysis_views.sql (BigQuery). Seluruh angka pada workbook ini berasal dari view di file ketiga, dan logika kueri utama sudah diuji ulang lewat dua implementasi lokal (DuckDB dan pandas) yang membandingkan seluruh 587 x 25 sel dan identik.

Sheet data_agregat
A1: NIK | B1: flags_allcondition_count | C1: flags_restructured_active_count | D1: flags_chargewriteoff_count | E1: plafond_credit_card_active_max | F1: installment_active_max | G1: balance_personal_loan_active_sum | H1: plafond_credit_card_active_sum | I1: installment_personal_loan_active_sum | J1: balance_credit_card_active_sum | K1: mob_active_avg | L1: dpd_nonbank_allcondition_last_12months_max | M1: collection_status_closed_unsecured_last_24months_max | N1: dpd_allcondition_last_3months_max | O1: collection_status_allcondition_last_6months_max | P1: collection_status_allcondition_last_12months_max | Q1: balance_unsecured_sum | R1: plafon_sum | S1: mob_allcondition_max | T1: balance_sum | U1: flags_active_dpd10plus_count | V1: flags_restructured_allcondition_unsecured_count | W1: slik_installment | X1: slik_exposure | Y1: whitelist_flag
A2: 1106200727740588 | B2: 16 | C2: 0 | D2: 0 | E2: 7450000 | F2: 1456417.3 | G2: 6449594.4 | H2: 7450000 | I2: 2135461.8 | J2: 2824016 | K2: 20.17 | L2: 0 | M2: 1 | N2: 0 | O2: 1 | P2: 1 | Q2: 9273610.4 | R2: 24607761 | S2: 103 | T2: 9273610.4 | U2: 0 | V2: 0 | W2: 2276662.6 | X2: 13899594 | Y2: 3.Customer Others
A3: 1171020723880386 | B3: 62 | C3: 0 | D3: 1 | F3: 19682200 | G3: 22190947 | H3: 0 | I3: 21731468 | J3: 0 | K3: 2.2 | L3: 2 | M3: 1 | N3: 1 | O3: 5 | P3: 5 | Q3: 22190947 | R3: 83952965 | S3: 132 | T3: 35756493 | U3: 0 | V3: 0 | W3: 24663044 | X3: 22190947 | Y3: 1.Customer has Writeoff
A4: 1171041229940602 | B4: 9 | C4: 0 | D4: 0 | F4: 675105.35 | G4: 1644000 | H4: 0 | I4: 831427.71 | J4: 0 | K4: 4 | L4: 0 | M4: 1 | N4: 0 | O4: 1 | P4: 1 | Q4: 1644000 | R4: 4304586.2 | S4: 32 | T4: 1644000 | U4: 0 | V4: 0 | W4: 831427.71 | X4: 1644000 | Y4: 3.Customer Others
A5: 1171091206990460 | B5: 2 | C5: 0 | D5: 0 | E5: 23840000 | F5: 644952.1 | G5: 0 | H5: 23840000 | I5: 0 | J5: 278431.23 | K5: 6 | M5: 1 | N5: 0 | O5: 1 | P5: 1 | Q5: 278431.23 | R5: 23840000 | S5: 14 | T5: 278431.23 | U5: 0 | V5: 0 | W5: 13921.56 | X5: 23840000 | Y5: 3.Customer Others
A6: 1173010831980916 | B6: 4 | C6: 0 | D6: 0 | E6: 44700000 | F6: 394316.05 | G6: 0 | H6: 44700000 | I6: 0 | J6: 22898692 | K6: 47 | M6: 1 | N6: 0 | O6: 1 | P6: 1 | Q6: 22898692 | R6: 44926480 | S6: 60 | T6: 22898692 | U6: 0 | V6: 0 | W6: 1144934.6 | X6: 44700000 | Y6: 3.Customer Others
A7: 1207230916890433 | B7: 1 | C7: 0 | D7: 0 | E7: 29800000 | F7: 616111.05 | G7: 0 | H7: 29800000 | I7: 0 | J7: 5800 | K7: 83 | N7: 0 | O7: 1 | P7: 1 | Q7: 5800 | R7: 29800000 | S7: 83 | T7: 5800 | U7: 0 | V7: 0 | W7: 290 | X7: 29800000 | Y7: 3.Customer Others
A8: 1207231226990994 | B8: 4 | C8: 0 | D8: 0 | E8: 134100000 | F8: 3290277.1 | G8: 0 | H8: 149000000 | I8: 0 | J8: 6159231.3 | K8: 25 | M8: 1 | N8: 0 | O8: 1 | P8: 1 | Q8: 6159231.3 | R8: 149000000 | S8: 25 | T8: 6159231.3 | U8: 0 | V8: 0 | W8: 307961.57 | X8: 149000000 | Y8: 3.Customer Others
A9: 1207260701800268 | B9: 2 | C9: 0 | D9: 0 | F9: 53376326 | G9: 0 | H9: 0 | I9: 0 | J9: 0 | K9: 55 | M9: 1 | N9: 0 | O9: 1 | P9: 1 | Q9: 0 | R9: 3605008381 | S9: 55 | T9: 3629203068 | U9: 0 | V9: 0 | W9: 53376326 | X9: 0 | Y9: 3.Customer Others
A10: 1208091007920582 | B10: 4 | C10: 0 | D10: 0 | E10: 13410000 | F10: 5450451.1 | G10: 0 | H10: 13410000 | I10: 0 | J10: 5781948 | K10: 31.5 | L10: 0 | M10: 1 | N10: 0 | O10: 1 | P10: 1 | Q10: 5781948 | R10: 426680873 | S10: 56 | T10: 95807834 | U10: 0 | V10: 0 | W10: 5739548.5 | X10: 13410000 | Y10: 3.Customer Others
A11: 1209080919000627 | B11: 67 | C11: 0 | D11: 0 | F11: 2721963 | G11: 2643690 | H11: 0 | I11: 3139010.1 | J11: 0 | K11: 2 | L11: 0 | M11: 1 | N11: 0 | O11: 1 | P11: 1 | Q11: 2643690 | R11: 4056881.1 | S11: 30 | T11: 2643690 | U11: 0 | V11: 0 | W11: 3139010.1 | X11: 2643690 | Y11: 3.Customer Others
A12: 1209191001950881 | B12: 2 | C12: 0 | D12: 0 | E12: 52150000 | F12: 763524.46 | G12: 0 | H12: 104300000 | I12: 0 | J12: 11619.3 | K12: 11 | N12: 0 | O12: 1 | P12: 1 | Q12: 11619.3 | R12: 104300000 | S12: 11 | T12: 11619.3 | U12: 0 | V12: 0 | W12: 580.97 | X12: 104300000 | Y12: 3.Customer Others
A13: 1209200519980410 | B13: 3 | C13: 0 | D13: 0 | E13: 7450000 | F13: 1964083.1 | G13: 0 | H13: 7450000 | I13: 1964083.1 | J13: 0 | K13: 26 | L13: 0 | M13: 1 | N13: 0 | O13: 1 | P13: 1 | Q13: 0 | R13: 70030000 | S13: 45 | T13: 0 | U13: 0 | V13: 0 | W13: 1964083.1 | X13: 7450000 | Y13: 3.Customer Others
A14: 1210010505930820 | B14: 1 | C14: 0 | D14: 0 | F14: 7949204.7 | G14: 0 | H14: 0 | I14: 0 | J14: 0 | K14: 20 | L14: 0 | N14: 0 | O14: 1 | P14: 1 | Q14: 0 | R14: 2.8511268e+08 | S14: 20 | T14: 2.659776e+08 | U14: 0 | V14: 0 | W14: 7949204.7 | X14: 0 | Y14: 3.Customer Others
A15: 1210010625980089 | B15: 1 | C15: 0 | D15: 0 | F15: 11630217 | G15: 0 | H15: 0 | I15: 0 | J15: 0 | K15: 16 | L15: 0 | N15: 0 | O15: 1 | P15: 1 | Q15: 0 | R15: 9.9229943e+08 | S15: 16 | T15: 9.123827e+08 | U15: 0 | V15: 0 | W15: 11630217 | X15: 0 | Y15: 3.Customer Others
A16: 1210191005960524 | B16: 179 | C16: 0 | D16: 0 | E16: 10430000 | F16: 1449287.5 | G16: 0 | H16: 10430000 | I16: 0 | J16: 0 | K16: 37.67 | L16: 0 | M16: 1 | N16: 0 | O16: 1 | P16: 1 | Q16: 8448308.6 | R16: 2.1058822e+08 | S16: 64 | T16: 1.4679897e+08 | U16: 0 | V16: 0 | W16: 2711223.6 | X16: 10430000 | Y16: 3.Customer Others
A17: 1216051228890239 | B17: 9 | C17: 0 | D17: 0 | E17: 151980000 | F17: 2605752 | G17: 0 | H17: 151980000 | I17: 0 | J17: 0 | K17: 91 | M17: 1 | N17: 0 | O17: 1 | P17: 1 | Q17: 0 | R17: 2.601212e+08 | S17: 91 | T17: 0 | U17: 0 | V17: 0 | W17: 0 | X17: 151980000 | Y17: 3.Customer Others
A18: 1271011220940844 | B18: 17 | C18: 0 | D18: 0 | E18: 53640000 | F18: 1660999.9 | G18: 0 | H18: 315135000 | I18: 0 | J18: 46760217 | K18: 39.1 | L18: 0 | M18: 2 | N18: 0 | O18: 1 | P18: 2 | Q18: 46760217 | R18: 437315000 | S18: 101 | T18: 46760217 | U18: 0 | V18: 0 | W18: 2338010.9 | X18: 315135000 | Y18: 3.Customer Others
A19: 1271021230950762 | B19: 4 | C19: 0 | D19: 0 | F19: 6780415.8 | G19: 0 | H19: 0 | I19: 0 | J19: 0 | K19: 52 | L19: 5 | M19: 1 | N19: 5 | O19: 2 | P19: 2 | Q19: 0 | R19: 2.4673018e+09 | S19: 61 | T19: 40410481 | U19: 0 | V19: 2 | W19: 6780415.8 | X19: 0 | Y19: 2.Customer has Restru
A20: 1271030104990024 | B20: 1 | C20: 0 | D20: 0 | E20: 59600000 | F20: 654449.53 | G20: 0 | H20: 59600000 | I20: 0 | J20: 31036313 | K20: 22 | N20: 0 | O20: 1 | P20: 1 | Q20: 31036313 | R20: 59600000 | S20: 22 | T20: 31036313 | U20: 0 | V20: 0 | W20: 1551815.7 | X20: 59600000 | Y20: 3.Customer Others
A21: 1271100325910063 | B21: 4 | C21: 0 | D21: 0 | E21: 15332100 | F21: 296274.87 | G21: 0 | H21: 25762100 | I21: 0 | J21: 18047037 | K21: 28.5 | L21: 0 | M21: 1 | N21: 0 | O21: 1 | P21: 1 | Q21: 18047037 | R21: 35447100 | S21: 44 | T21: 18047037 | U21: 0 | V21: 0 | W21: 902351.84 | X21: 25762100 | Y21: 3.Customer Others
A22: 1271120318960339 | B22: 23 | C22: 0 | D22: 0 | E22: 12963000 | F22: 408052.62 | G22: 637835.08 | H22: 26373000 | I22: 441619.54 | J22: 240587.07 | K22: 42.2 | L22: 0 | M22: 1 | N22: 26 | O22: 2 | P22: 2 | Q22: 878422.15 | R22: 1.4291771e+08 | S22: 86 | T22: 878422.15 | U22: 2 | V22: 0 | W22: 453648.89 | X22: 27010835 | Y22: 3.Customer Others
A23: 1271141214930172 | B23: 2 | C23: 0 | D23: 0 | E23: 38740000 | F23: 1048047.2 | G23: 0 | H23: 43210000 | I23: 0 | J23: 2677439.8 | K23: 27 | N23: 0 | O23: 1 | P23: 1 | Q23: 2677439.8 | R23: 43210000 | S23: 31 | T23: 2677439.8 | U23: 0 | V23: 0 | W23: 133871.99 | X23: 43210000 | Y23: 3.Customer Others
A24: 1271170505830383 | B24: 10 | C24: 0 | D24: 6 | F24: 788168.82 | G24: 3347174.4 | H24: 0 | I24: 788168.82 | J24: 0 | K24: 49 | L24: 1247 | N24: 3119 | O24: 5 | P24: 5 | Q24: 46078149 | R24: 67809024 | S24: 152 | T24: 46078149 | U24: 1 | V24: 0 | W24: 788168.82 | X24: 3347174.4 | Y24: 1.Customer has Writeoff
A25: 1271170716800250 | B25: 4 | C25: 0 | D25: 0 | E25: 169120960 | F25: 3095949 | G25: 0 | H25: 215310960 | I25: 0 | J25: 15661338 | K25: 63 | L25: 0 | N25: 0 | O25: 1 | P25: 1 | Q25: 15661338 | R25: 224250960 | S25: 144 | T25: 15661338 | U25: 0 | V25: 0 | W25: 783066.89 | X25: 215310960 | Y25: 3.Customer Others
A26: 1271191230950687 | B26: 5 | C26: 0 | D26: 0 | E26: 149000000 | F26: 4030950.6 | G26: 0 | H26: 172840000 | I26: 0 | J26: 1.2299732e+08 | K26: 17 | M26: 1 | N26: 3 | O26: 2 | P26: 2 | Q26: 1.2299732e+08 | R26: 333760000 | S26: 34 | T26: 1.2299732e+08 | U26: 0 | V26: 0 | W26: 6149866.2 | X26: 172840000 | Y26: 3.Customer Others
A27: 1271200829840663 | B27: 4 | C27: 0 | D27: 0 | F27: 24352533 | G27: 0 | H27: 0 | I27: 0 | J27: 0 | K27: 30 | L27: 0 | N27: 0 | O27: 1 | P27: 1 | Q27: 0 | R27: 4.7792555e+09 | S27: 142 | T27: 1.0742922e+09 | U27: 0 | V27: 0 | W27: 39585890 | X27: 0 | Y27: 3.Customer Others
A28: 1272021026850992 | B28: 3 | C28: 0 | D28: 0 | E28: 144439110 | F28: 2642026.9 | G28: 0 | H28: 218939110 | I28: 0 | J28: 83350101 | K28: 101.5 | L28: 0 | N28: 0 | O28: 1 | P28: 1 | Q28: 83350101 | R28: 233839110 | S28: 132 | T28: 83350101 | U28: 0 | V28: 0 | W28: 4167505.1 | X28: 218939110 | Y28: 3.Customer Others
A29: 1272060228960033 | B29: 11 | C29: 0 | D29: 3 | E29: 23989000 | F29: 517706.85 | G29: 0 | H29: 23989000 | I29: 0 | J29: 18439889 | K29: 10 | L29: 1463 | M29: 5 | N29: 1463 | O29: 5 | P29: 5 | Q29: 21385059 | R29: 42810644 | S29: 63 | T29: 21385059 | U29: 0 | V29: 0 | W29: 921994.47 | X29: 23989000 | Y29: 1.Customer has Writeoff
A30: 1272060517910404 | B30: 17 | C30: 0 | D30: 0 | E30: 3.3979378e+08 | F30: 7030390.2 | G30: 0 | H30: 5.7812e+08 | I30: 0 | J30: 3.2675533e+08 | K30: 37.2 | L30: 0 | M30: 1 | N30: 0 | O30: 1 | P30: 2 | Q30: 3.2675533e+08 | R30: 1.3364648e+09 | S30: 132 | T30: 3.2675533e+08 | U30: 1 | V30: 0 | W30: 16337767 | X30: 5.7812e+08 | Y30: 3.Customer Others
A31: 1275030606840527 | B31: 4 | C31: 0 | D31: 0 | F31: 347966.95 | G31: 0 | H31: 0 | I31: 0 | J31: 0 | K31: 28 | N31: 0 | O31: 1 | P31: 2 | Q31: 0 | R31: 86470237 | S31: 125 | T31: 58850786 | U31: 0 | V31: 0 | W31: 347966.95 | X31: 0 | Y31: 3.Customer Others
A32: 1276020509010488 | B32: 13 | C32: 0 | D32: 0 | E32: 73010000 | F32: 1994217.3 | G32: 0 | H32: 163900000 | I32: 0 | J32: 10057447 | K32: 20 | M32: 1 | N32: 0 | O32: 1 | P32: 1 | Q32: 10057447 | R32: 4.1767752e+08 | S32: 59 | T32: 10057447 | U32: 0 | V32: 0 | W32: 502872.34 | X32: 163900000 | Y32: 3.Customer Others
A33: 1276051014880801 | B33: 1 | C33: 0 | D33: 0 | F33: 3244803 | G33: 0 | H33: 0 | I33: 3244803 | J33: 0 | K33: 14 | N33: 0 | O33: 1 | P33: 1 | Q33: 0 | R33: 74500000 | S33: 14 | T33: 0 | U33: 0 | V33: 0 | W33: 3244803 | X33: 0 | Y33: 3.Customer Others
A34: 1277011117940577 | B34: 4 | C34: 0 | D34: 0 | E34: 223500000 | F34: 6046425.9 | G34: 0 | H34: 298000000 | I34: 0 | J34: 2677405.4 | K34: 29.67 | M34: 1 | N34: 0 | O34: 1 | P34: 1 | Q34: 2677405.4 | R34: 298000000 | S34: 67 | T34: 2677405.4 | U34: 0 | V34: 0 | W34: 133870.27 | X34: 298000000 | Y34: 3.Customer Others
A35: 1305020319010996 | B35: 41 | C35: 0 | D35: 0 | F35: 1902811.9 | G35: 15811579 | H35: 0 | I35: 2938126.1 | J35: 0 | K35: 3 | L35: 0 | M35: 1 | N35: 0 | O35: 1 | P35: 1 | Q35: 21031219 | R35: 27105801 | S35: 22 | T35: 21031219 | U35: 0 | V35: 0 | W35: 3135366.1 | X35: 15811579 | Y35: 3.Customer Others
A36: 1305140730980981 | B36: 2 | C36: 0 | D36: 0 | E36: 93870000 | F36: 2589406.9 | G36: 0 | H36: 93870000 | I36: 0 | J36: 0 | K36: 18 | M36: 1 | N36: 0 | O36: 2 | P36: 2 | Q36: 0 | R36: 108770000 | S36: 18 | T36: 0 | U36: 0 | V36: 0 | W36: 0 | X36: 93870000 | Y36: 3.Customer Others
A37: 1307011006950992 | B37: 30 | C37: 0 | D37: 0 | E37: 71520000 | F37: 1245778.8 | G37: 0 | H37: 174615633 | I37: 0 | J37: 26707809 | K37: 21.75 | M37: 1 | N37: 0 | O37: 1 | P37: 1 | Q37: 26707809 | R37: 2.4418254e+08 | S37: 60 | T37: 26707809 | U37: 0 | V37: 0 | W37: 1335390.4 | X37: 174615633 | Y37: 3.Customer Others
A38: 1311010110830281 | B38: 2 | C38: 0 | D38: 0 | G38: 0 | H38: 0 | I38: 0 | J38: 0 | M38: 5 | Q38: 0 | R38: 119200000 | S38: 103 | T38: 0 | U38: 0 | V38: 0 | W38: 0 | X38: 0 | Y38: 3.Customer Others
A39: 1371110218930180 | B39: 10 | C39: 0 | D39: 0 | F39: 156986.97 | G39: 212827.68 | H39: 0 | I39: 156986.97 | J39: 0 | K39: 3 | M39: 1 | N39: 0 | O39: 1 | P39: 1 | Q39: 212827.68 | R39: 1096345 | S39: 28 | T39: 212827.68 | U39: 0 | V39: 0 | W39: 156986.97 | X39: 212827.68 | Y39: 3.Customer Others
A40: 1371110418860889 | B40: 11 | C40: 0 | D40: 5 | F40: 2097890.1 | G40: 0 | H40: 0 | I40: 0 | J40: 0 | K40: 53 | L40: 1584 | M40: 1 | N40: 1584 | O40: 5 | P40: 5 | Q40: 6529084.6 | R40: 60618202 | S40: 53 | T40: 82389366 | U40: 1 | V40: 0 | W40: 2097890.1 | X40: 0 | Y40: 1.Customer has Writeoff
...

Sheet data_customer
A1: NIK | B1: whitelist_flag | C1: slik_behavior_segment | D1: kol_6m_label | E1: kol_12m_label | F1: risk_band_6m | G1: collection_status_allcondition_last_6months_max | H1: collection_status_allcondition_last_12months_max | I1: dpd_allcondition_last_3months_max | J1: flags_allcondition_count | K1: flags_active_dpd10plus_count | L1: slik_exposure | M1: slik_installment | N1: balance_sum | O1: mob_allcondition_max | P1: is_thin_file | Q1: npl_now_active | R1: ever_npl_12m | S1: ever_dpd_3m | T1: age_group | U1: gender | V1: marital_status | W1: pendidikan | X1: pekerjaan | Y1: kab_kota | Z1: industry
A2: 1106200727740588 | B2: 3.Customer Others | C2: A. Clean & Current | D2: Kol 1 - Lancar | E2: Kol 1 - Lancar | F2: 0. Lancar | G2: 1 | H2: 1 | I2: 0 | J2: 16 | K2: 0 | L2: 13899594 | M2: 2276662.6 | N2: 9273610.4 | O2: 103 | P2: 0 | Q2: 0 | R2: 0 | S2: 0 | T2: 45-49 | U2: MALE | V2: Married | W2: S-1 | X2: Administrasi umum | Y2: Kab. Purwakarta | Z2: Industry
A3: 1171020723880386 | B3: 1.Customer has Writeoff | C3: E. Writeoff | D3: Kol 5 - Macet | E3: Kol 5 - Macet | F3: 2. NPL (Kol 3-5) | G3: 5 | H3: 5 | I3: 1 | J3: 62 | K3: 0 | L3: 22190947 | M3: 24663044 | N3: 35756493 | O3: 132 | P3: 0 | Q3: 0 | R3: 1 | S3: 1 | T3: 35-39 | U3: MALE | V3: Single | W3: S-1 | X3: Lain-lain | Y3: Wil. Kota Jakarta Selatan | Z3: Banking / Insurance / Finance
A4: 1171041229940602 | B4: 3.Customer Others | C4: A. Clean & Current | D4: Kol 1 - Lancar | E4: Kol 1 - Lancar | F4: 0. Lancar | G4: 1 | H4: 1 | I4: 0 | J4: 9 | K4: 0 | L4: 1644000 | M4: 831427.71 | N4: 1644000 | O4: 32 | P4: 0 | Q4: 0 | R4: 0 | S4: 0 | T4: 25-29 | U4: MALE | V4: Married | W4: S-2 | X4: Wiraswasta | Y4: Kota Banda Aceh | Z4: Transportation
A5: 1171091206990460 | B5: 3.Customer Others | C5: A. Clean & Current | D5: Kol 1 - Lancar | E5: Kol 1 - Lancar | F5: 0. Lancar | G5: 1 | H5: 1 | I5: 0 | J5: 2 | K5: 0 | L5: 23840000 | M5: 13921.56 | N5: 278431.23 | O5: 14 | P5: 0 | Q5: 0 | R5: 0 | S5: 0 | T5: 20-24 | U5: MALE | V5: Single | W5: S-1 | X5: Pegawai Pemerintahan/Lembaga Negara (selain Pejabat/Penyelenggara Negara) | Y5: Kota Banda Aceh | Z5: Trading
A6: 1173010831980916 | B6: 3.Customer Others | C6: A. Clean & Current | D6: Kol 1 - Lancar | E6: Kol 1 - Lancar | F6: 0. Lancar | G6: 1 | H6: 1 | I6: 0 | J6: 4 | K6: 0 | L6: 44700000 | M6: 1144934.6 | N6: 22898692 | O6: 60 | P6: 0 | Q6: 0 | R6: 0 | S6: 0 | T6: 25-29 | U6: FEMALE | V6: Single | W6: S-1 | X6: Lain-lain | Y6: Wil. Kota Jakarta Selatan | Z6: Information and Technology
A7: 1207230916890433 | B7: 3.Customer Others | C7: A. Clean & Current | D7: Kol 1 - Lancar | E7: Kol 1 - Lancar | F7: 0. Lancar | G7: 1 | H7: 1 | I7: 0 | J7: 1 | K7: 0 | L7: 29800000 | M7: 290 | N7: 5800 | O7: 83 | P7: 0 | Q7: 0 | R7: 0 | S7: 0 | T7: 30-34 | U7: MALE | V7: Single | W7: Tanpa Gelar | X7: Wiraswasta | Y7: Kab. Bengkalis | Z7: Automotive
A8: 1207231226990994 | B8: 3.Customer Others | C8: A. Clean & Current | D8: Kol 1 - Lancar | E8: Kol 1 - Lancar | F8: 0. Lancar | G8: 1 | H8: 1 | I8: 0 | J8: 4 | K8: 0 | L8: 149000000 | M8: 307961.57 | N8: 6159231.3 | O8: 25 | P8: 0 | Q8: 0 | R8: 0 | S8: 0 | T8: 25-29 | U8: FEMALE | V8: Single | W8: S-1 | X8: Lain-lain | Y8: Kab. Deli Serdang | Z8: Healthcare
A9: 1207260701800268 | B9: 3.Customer Others | C9: A. Clean & Current | D9: Kol 1 - Lancar | E9: Kol 1 - Lancar | F9: 0. Lancar | G9: 1 | H9: 1 | I9: 0 | J9: 2 | K9: 0 | L9: 0 | M9: 53376326 | N9: 3629203068 | O9: 55 | P9: 1 | Q9: 0 | R9: 0 | S9: 0 | T9: 40-44 | U9: MALE | V9: Married | W9: S-2 | X9: Dokter | Y9: Kab. Ketapang | Z9: Healthcare
A10: 1208091007920582 | B10: 3.Customer Others | C10: A. Clean & Current | D10: Kol 1 - Lancar | E10: Kol 1 - Lancar | F10: 0. Lancar | G10: 1 | H10: 1 | I10: 0 | J10: 4 | K10: 0 | L10: 13410000 | M10: 5739548.5 | N10: 95807834 | O10: 56 | P10: 0 | Q10: 0 | R10: 0 | S10: 0 | T10: 30-34 | U10: MALE | V10: Single | W10: S-1 | X10: Lain-lain | Y10: Kab. Simalungun | Z10: Banking/Insurance/Financial/ BPR
A11: 1209080919000627 | B11: 3.Customer Others | C11: A. Clean & Current | D11: Kol 1 - Lancar | E11: Kol 1 - Lancar | F11: 0. Lancar | G11: 1 | H11: 1 | I11: 0 | J11: 67 | K11: 0 | L11: 2643690 | M11: 3139010.1 | N11: 2643690 | O11: 30 | P11: 0 | Q11: 0 | R11: 0 | S11: 0 | T11: 20-24 | U11: MALE | V11: Single | W11: S-1 | X11: Lain-lain | Y11: Kab. Asahan | Z11: Distribution
A12: 1209191001950881 | B12: 3.Customer Others | C12: A. Clean & Current | D12: Kol 1 - Lancar | E12: Kol 1 - Lancar | F12: 0. Lancar | G12: 1 | H12: 1 | I12: 0 | J12: 2 | K12: 0 | L12: 104300000 | M12: 580.97 | N12: 11619.3 | O12: 11 | P12: 0 | Q12: 0 | R12: 0 | S12: 0 | T12: 25-29 | U12: MALE | V12: Single | W12: Lainnya | X12: Wiraswasta | Y12: Kab. Asahan | Z12: Information and Technology
A13: 1209200519980410 | B13: 3.Customer Others | C13: A. Clean & Current | D13: Kol 1 - Lancar | E13: Kol 1 - Lancar | F13: 0. Lancar | G13: 1 | H13: 1 | I13: 0 | J13: 3 | K13: 0 | L13: 7450000 | M13: 1964083.1 | N13: 0 | O13: 45 | P13: 0 | Q13: 0 | R13: 0 | S13: 0 | T13: 25-29 | U13: MALE | V13: Single | W13: Diploma 3 | X13: Pegawai Pemerintahan/Lembaga Negara (selain Pejabat/Penyelenggara Negara) | Y13: Kab. Asahan | Z13: Government
... A37: 1307011006950992 | B37: 3.Customer Others | C37: A. Clean & Current | D37: Kol 1 - Lancar | E37: Kol 1 - Lancar | F37: 0. Lancar | G37: 1 | H37: 1 | I37: 0 | J37: 30 | K37: 0 | L37: 174615633 | M37: 1335390.4 | N37: 26707809 | O37: 60 | P37: 0 | Q37: 0 | R37: 0 | S37: 0 | T37: 25-29 | U37: MALE | V37: Single | W37: S-1 | X37: Lain-lain | Y37: Kab. Limapuluh Kota | Z37: Banking / Insurance / Finance
A38: 1311010110830281 | B38: 3.Customer Others | C38: A. Clean & Current | D38: Tanpa Riwayat 6 Bln | E38: Tanpa Riwayat 12 Bln | F38: 3. Tanpa Riwayat | H38: 1 | I38: 0 | J38: 2 | K38: 0 | L38: 0 | M38: 0 | N38: 0 | O38: 103 | P38: 1 | Q38: 0 | R38: 0 | S38: 0 | T38: 40-44 | U38: MALE | V38: Single | W38: Tanpa Gelar | X38: Wiraswasta | Y38: Kab. Solok Selatan | Z38: Distribution
A39: 1371110218930180 | B39: 3.Customer Others | C39: A. Clean & Current | D39: Kol 1 - Lancar | E39: Kol 1 - Lancar | F39: 0. Lancar | G39: 1 | H39: 1 | I39: 0 | J39: 10 | K39: 0 | L39: 212827.68 | M39: 156986.97 | N39: 212827.68 | O39: 28 | P39: 0 | Q39: 0 | R39: 0 | S39: 0 | T39: 35-39 | U39: MALE | V39: Single | W39: Tanpa Gelar | X39: Lain-lain | Y39: Kab. Tangerang | Z39: Motorcycle/Car Dealers
A40: 1371110418860889 | B40: 1.Customer has Writeoff | C40: E. Writeoff | D40: Kol 5 - Macet | E40: Kol 5 - Macet | F40: 2. NPL (Kol 3-5) | G40: 5 | H40: 5 | I40: 1584 | J40: 11 | K40: 1 | L40: 0 | M40: 2097890.1 | N40: 82389366 | O40: 53 | P40: 1 | Q40: 1 | R40: 1 | S40: 1 | T40: 30-34 | U40: FEMALE | V40: Married | W40: S-1 | X40: Ibu Rumah Tangga | Y40: Kota Padang | Z40: Culinary
A41: 1375011005990542 | B41: 3.Customer Others | C41: A. Clean & Current | D41: Kol 1 - Lancar | E41: Kol 1 - Lancar | F41: 0. Lancar | G41: 1 | H41: 1 | I41: 0 | J41: 1 | K41: 0 | L41: 29800000 | M41: 1066322.5 | N41: 21326449 | O41: 8 | P41: 0 | Q41: 0 | R41: 0 | S41: 0 | T41: 25-29 | U41: MALE | V41: Single | W41: Lainnya | X41: Pelajar/Mahasiswa | Y41: Wil. Kota Jakarta Barat | Z41: Information and Technology
A42: 1375020508990025 | B42: 3.Customer Others | C42: A. Clean & Current | D42: Kol 1 - Lancar | E42: Kol 1 - Lancar | F42: 0. Lancar | G42: 1 | H42: 1 | I42: 0 | J42: 2 | K42: 0 | L42: 32780000 | M42: 87233.77 | N42: 1744675.4 | O42: 60 | P42: 0 | Q42: 0 | R42: 0 | S42: 0 | T42: 25-29 | U42: FEMALE | V42: Single | W42: S-1 | X42: Pegawai Pemerintahan/Lembaga Negara (selain Pejabat/Penyelenggara Negara) | Y42: Kota Jambi | Z42: Others
A43: 1401040827950804 | B43: 1.Customer has Writeoff | C43: E. Writeoff | D43: Kol 5 - Macet | E43: Kol 5 - Macet | F43: 2. NPL (Kol 3-5) | G43: 5 | H43: 5 | I43: 277 | J43: 37 | K43: 0 | L43: 4629761.4 | M43: 1027269.5 | N43: 22039847 | O43: 29 | P43: 0 | Q43: 0 | R43: 1 | S43: 1 | T43: 25-29 | U43: MALE | V43: Single | W43: S-1 | X43: Lain-lain | Y43: Kab. Kampar | Z43: Trading
A44: 1403090821000340 | B44: 3.Customer Others | C44: A. Clean & Current | D44: Kol 1 - Lancar | E44: Kol 1 - Lancar | F44: 0. Lancar | G44: 1 | H44: 1 | I44: 0 | J44: 1 | K44: 0 | L44: 43210000 | M44: 808467.85 | N44: 16169357 | O44: 3 | P44: 0 | Q44: 0 | R44: 0 | S44: 0 | T44: 20-24 | U44: MALE | V44: Single | W44: Lainnya | X44: Pegawai Pemerintahan/Lembaga Negara (selain Pejabat/Penyelenggara Negara) | Y44: Kab. Bengkalis | Z44: Government
A45: 1471040301850647 | B45: 3.Customer Others | C45: A. Clean & Current | D45: Kol 1 - Lancar | E45: Kol 1 - Lancar | F45: 0. Lancar | G45: 1 | H45: 1 | I45: 0 | J45: 16 | K45: 0 | L45: 312900000 | M45: 16729845 | N45: 8.3799111e+08 | O45: 144 | P45: 0 | Q45: 0 | R45: 0 | S45: 0 | T45: 35-39 | U45: MALE | V45: Single | W45: S-1 | X45: Lain-lain | Y45: Kota Pekanbaru | Z45: Government
A46: 1471041120870466 | B46: 3.Customer Others | C46: A. Clean & Current | D46: Kol 1 - Lancar | E46: Kol 1 - Lancar | F46: 0. Lancar | G46: 1 | H46: 1 | I46: 0 | J46: 5 | K46: 0 | L46: 888338421 | M46: 10730512 | N46: 888338421 | O46: 114 | P46: 0 | Q46: 0 | R46: 0 | S46: 0 | T46: 35-39 | U46: MALE | V46: Married | W46: S-1 | X46: Lain-lain | Y46: Kota Batam | Z46: Trading
A47: 1471060728920958 | B47: 3.Customer Others | C47: A. Clean & Current | D47: Kol 1 - Lancar | E47: Kol 1 - Lancar | F47: 0. Lancar | G47: 1 | H47: 1 | I47: 0 | J47: 5 | K47: 0 | L47: 0 | M47: 813602.94 | N47: 27939879 | O47: 136 | P47: 1 | Q47: 0 | R47: 0 | S47: 0 | T47: 35-39 | U47: FEMALE | V47: Married | W47: S-1 | X47: Lain-lain | Y47: Kota Pekanbaru | Z47: Business Services
A48: 1471090612740375 | B48: 3.Customer Others | C48: A. Clean & Current | D48: Kol 1 - Lancar | E48: Kol 1 - Lancar | F48: 0. Lancar | G48: 1 | H48: 1 | I48: 0 | J48: 18 | K48: 0 | L48: 691360000 | M48: 18292057 | N48: 1.0503008e+08 | O48: 191 | P48: 0 | Q48: 0 | R48: 0 | S48: 0 | T48: 50-54 | U48: MALE | V48: Married | W48: S-1 | X48: Polisi | Y48: Kota Pekanbaru | Z48: Construction
A49: 1471120204870079 | B49: 1.Customer has Writeoff | C49: E. Writeoff | D49: Kol 5 - Macet | E49: Kol 5 - Macet | F49: 2. NPL (Kol 3-5) | G49: 5 | H49: 5 | I49: 152 | J49: 47 | K49: 1 | L49: 530280.21 | M49: 490697.01 | N49: 647385.21 | O49: 22 | P49: 0 | Q49: 1 | R49: 1 | S49: 1 | T49: 35-39 | U49: MALE | V49: Married | W49: Tanpa Gelar | X49: Lain-lain | Y49: Kab. Kampar | Z49: Others - Other
A50: 1501090427950292 | B50: 3.Customer Others | C50: B. Past Due Ringan | D50: Kol 2 - Dalam Perhatian Khusus | E50: Kol 2 - Dalam Perhatian Khusus | F50: 1. Perhatian Khusus | G50: 2 | H50: 2 | I50: 1 | J50: 107 | K50: 0 | L50: 2.6045119e+08 | M50: 42207162 | N50: 2.1282122e+08 | O50: 45 | P50: 0 | Q50: 0 | R50: 0 | S50: 1 | T50: 25-29 | U50: MALE | V50: Single | W50: S-1 | X50: Lain-lain | Y50: Kab. Kerinci | Z50: Others - Other
... A53: 1601130617010835 | B53: 3.Customer Others | C53: A. Clean & Current | D53: Kol 1 - Lancar | E53: Kol 1 - Lancar | F53: 0. Lancar | G53: 1 | H53: 1 | I53: 0 | J53: 37 | K53: 0 | L53: 7450000 | M53: 467638.84 | N53: 0 | O53: 59 | P53: 0 | Q53: 0 | R53: 0 | S53: 0 | T53: 25-29 | U53: FEMALE | V53: Married | W53: S-1 | X53: Lain-lain | Y53: Kab. Ogan Komering Ulu | Z53: Gas Station
A54: 1604100703940734 | B54: 3.Customer Others | C54: A. Clean & Current | D54: Tanpa Riwayat 6 Bln | E54: Tanpa Riwayat 12 Bln | F54: 3. Tanpa Riwayat | H54: 1 | I54: 0 | J54: 1 | K54: 0 | L54: 0 | M54: 0 | N54: 0 | O54: 74 | P54: 1 | Q54: 0 | R54: 0 | S54: 0 | T54: 30-34 | U54: FEMALE | V54: Single | W54: S-1 | X54: Lain-lain | Y54: Kab. Lampung Utara | Z54: Others
